<?xml version="1.0" ?>
<!-- =================================================================================== -->
<!-- |    This document was autogenerated by xacro from xacro/pendulum.xacro           | -->
<!-- |    EDITING THIS FILE BY HAND IS NOT RECOMMENDED                                 | -->
<!-- =================================================================================== -->
<robot name="pendulum_robot" xmlns:xacro="http://www.ros.org/wiki/xacro">
  <link name="base_link"/>
  <link name="base">
    <visual>
      <geometry>
        <box size=".1 .1 .05"/>
      </geometry>
      <material name="red"/>
    </visual>
  </link>
  <joint name="root2base" type="prismatic">
    <parent link="base_link"/>
    <child link="base"/>
    <limit effort="1000" lower="-1" upper="1" velocity="0.5"/>
    <origin rpy="0 0 0" xyz="0 0 0"/>
  </joint>
  <link name="pendulum1">
    <visual>
      <geometry>
        <cylinder length="0.5" radius="0.01"/>
      </geometry>
      <material name="blue"/>
    </visual>
    <collision>
      <geometry>
        <cylinder length="0.5" radius="0.01"/>
      </geometry>
    </collision>
    <inertial>
      <mass value="1.2246"/>
      <inertia ixx="0.10205" ixy="0" ixz="0" iyy="0" iyz="0" izz="0.10205"/>
    </inertial>
  </link>
  <link name="pendulum2">
    <visual>
      <geometry>
        <cylinder length="0.5" radius="0.01"/>
      </geometry>
      <material name="blue"/>
    </visual>
    <collision>
      <geometry>
        <cylinder length="0.48" radius="0.01"/>
      </geometry>
    </collision>
    <inertial>
      <mass value="1.175616"/>
      <inertia ixx="0.09404928" ixy="0" ixz="0" iyy="0" iyz="0" izz="0.09404928"/>
    </inertial>
  </link>
  <joint name="p2base" type="fixed">
    <parent link="base"/>
    <child link="pendulum1"/>
    <origin rpy="0 0 0" xyz=".06 0 .25"/>
  </joint>
  <joint name="p2p" type="fixed">
    <parent link="pendulum1"/>
    <child link="pendulum2"/>
    <origin rpy="0 0 0" xyz="-.02 0 .48"/>
  </joint>
  <material name="red">
    <color rgba="1 0 0 1"/>
  </material>
  <material name="blue">
    <color rgba="0 0 1 1"/>
  </material>
</robot>

